Workbook

Sheet All Districts
A1: District | B1: Code | C1: Incumbent Party | D1: 2022 Winners | G1: 2020 President | I1: 2016 President | K1: 2020 Census Voting Age Population by Race | Q1: 2020 ACS Adult Educational Attainment | S1: Non-College White Share | T1: Party | U1: Candidate Status | V1: Candidate Name | X1: First Elected | Y1: Race / Ethnicity | Z1: LGBTQ | AA1: Party | AB1: Candidate Status | AC1: Candidate Name | AE1: First Elected | AF1: Race / Ethnicity
D2: Name | E2: Party | F2: Outcome | G2: Biden | H2: Trump | I2: Clinton | J2: Trump | K2: White (Non-Hispanic, Single Race) | L2: Hispanic/Latino | M2: Black | N2: Asian | O2: Native | P2: Pacific | Q2: Bachelor's Degree or Higher | R2: White BA (Bachelor's Degree or Higher Among Whites Only) | V2: First | W2: Last | AC2: First | AD2: Last
A3: Nationwide | B3: USA | C3: 222D - 213R | G3: 51.4 | H3: 46.9 | I3: 48.4 | J3: 46.3 | K3: 60.8 | L3: 16.8 | M3: 13.2 | N3: 7 | O3: 2.7 | P3: 0.4 | Q3: 32.9 | R3: 36.5 | S3: 42.9
A4: Alabama's 7th | B4: AL-07 | C4: Democratic | D4: Terri Sewell | E4: Democratic | F4: Hold | G4: 65.6 | H4: 33.6 | I4: 64.1 | J4: 33.5 | K4: 38.6 | L4: 3.7 | M4: 55.3 | N4: 1.5 | O4: 1.3 | P4: 0.1 | Q4: 22.8 | R4: 32.2 | S4: 27.3 | T4: Dem | U4: Incumbent | V4: Terri | W4: Sewell | X4: 2010 | Y4: Black | Z4: No
A5: Arizona's 3rd | B5: AZ-03 | C5: Democratic | D5: Ruben Gallego | E5: Democratic | F5: Hold | G5: 74.5 | H5: 23.9 | I5: 71.4 | J5: 21.5 | K5: 23.8 | L5: 58.2 | M5: 11.9 | N5: 3.8 | O5: 5.1 | P5: 0.5 | Q5: 16.1 | R5: 31.5 | S5: 20.5 | T5: Dem | U5: Incumbent | V5: Ruben | W5: Gallego | X5: 2014 | Y5: Hispanic - Mexican/Colombian | Z5: No
A6: Arizona's 4th | B6: AZ-04 | C6: Democratic | D6: Greg Stanton | E6: Democratic | F6: Hold | G6: 54.2 | H6: 43.9 | I6: 46.5 | J6: 44.1 | K6: 59.4 | L6: 23.1 | M6: 6.6 | N6: 7.3 | O6: 4.3 | P6: 0.6 | Q6: 35.4 | R6: 39.3 | S6: 40.7 | T6: Dem | U6: Incumbent | V6: Greg | W6: Stanton | X6: 2018 | Y6: White | Z6: No
A7: Arizona's 7th | B7: AZ-07 | C7: Democratic | D7: Raúl Grijalva | E7: Democratic | F7: Hold | G7: 65.6 | H7: 32.9 | I7: 63.4 | J7: 29.8 | K7: 32.9 | L7: 55.5 | M7: 4.9 | N7: 3 | O7: 5.8 | P7: 0.4 | Q7: 19.8 | R7: 31.9 | S7: 25.6 | T7: Dem | U7: Incumbent | V7: Raúl | W7: Grijalva | X7: 2002 | Y7: Hispanic - Mexican | Z7: No
A8: California's 2nd | B8: CA-02 | C8: Democratic | D8: Jared Huffman | E8: Democratic | F8: Hold | G8: 73.5 | H8: 24 | I8: 68.9 | J8: 23.4 | K8: 68.4 | L8: 17.9 | M8: 2.6 | N8: 5.9 | O8: 5.4 | P8: 0.6 | Q8: 41.7 | R8: 46.8 | S8: 41.5 | T8: Dem | U8: Incumbent | V8: Jared | W8: Huffman | X8: 2012 | Y8: White | Z8: No
A9: California's 4th | B9: CA-04 | C9: Democratic | D9: Mike Thompson | E9: Democratic | F9: Hold | G9: 67.1 | H9: 30.5 | I9: 63.7 | J9: 29.3 | K9: 55.3 | L9: 27.5 | M9: 4.1 | N9: 10 | O9: 4 | P9: 0.8 | Q9: 34.2 | R9: 40.3 | S9: 38.9 | T9: Dem | U9: Incumbent | V9: Mike | W9: Thompson | X9: 1998 | Y9: White | Z9: No
A10: California's 6th | B10: CA-06 | C10: Democratic | D10: Ami Bera | E10: Democratic | F10: Hold | G10: 57.9 | H10: 39.4 | I10: 54.8 | J10: 38 | K10: 51.1 | L10: 20.3 | M10: 11.1 | N10: 14.7 | O10: 3.8 | P10: 1.5 | Q10: 28.8 | R10: 30.7 | S10: 39.9 | T10: Dem | U10: Incumbent | V10: Ami | W10: Bera | X10: 2012 | Y10: Asian - Indian | Z10: No
A11: California's 7th | B11: CA-07 | C11: Democratic | D11: Doris Matsui | E11: Democratic | F11: Hold | G11: 67.4 | H11: 30.3 | I11: 66.3 | J11: 27.7 | K11: 35 | L11: 24.1 | M11: 12.4 | N11: 26 | O11: 3.5 | P11: 2.4 | Q11: 31.7 | R11: 40.5 | S11: 24.6 | T11: Dem | U11: Incumbent | V11: Doris | W11: Matsui | X11: 2005 Special | Y11: Asian - Japanese | Z11: No
A12: California's 8th | B12: CA-08 | C12: Democratic | D12: John Garamendi | E12: Democratic | F12: Hold | G12: 76 | H12: 22 | I12: 75.3 | J12: 19.4 | K12: 26.9 | L12: 31.5 | M12: 17.7 | N12: 22.4 | O12: 3.6 | P12: 1.6 | Q12: 28.6 | R12: 37.1 | S12: 21.5 | T12: Dem | U12: Incumbent | V12: John | W12: Garamendi | X12: 2009 Special | Y12: White | Z12: No
A13: California's 10th | B13: CA-10 | C13: Democratic | D13: Mark DeSaulnier | E13: Democratic | F13: Hold | G13: 68.6 | H13: 29.3 | I13: 65.1 | J13: 28.9 | K13: 51.3 | L13: 16.7 | M13: 5.8 | N13: 24.5 | O13: 2.3 | P13: 0.9 | Q13: 53.8 | R13: 55.6 | S13: 26.9 | T13: Dem | U13: Incumbent | V13: Mark | W13: DeSaulnier | X13: 2014 | Y13: White | Z13: No
A14: California's 11th | B14: CA-11 | C14: Democratic | D14: Nancy Pelosi | E14: Democratic | F14: Hold | G14: 86.3 | H14: 11.7 | I14: 86 | J14: 8.9 | K14: 44.6 | L14: 13.2 | M14: 6.6 | N14: 34.2 | O14: 1.9 | P14: 0.7 | Q14: 63.4 | R14: 78.3 | S14: 10.8 | T14: Dem | U14: Incumbent | V14: Nancy | W14: Pelosi | X14: 1987 Special | Y14: White | Z14: No
A15: California's 12th | B15: CA-12 | C15: Democratic | D15: Barbara Lee | E15: Democratic | F15: Hold | G15: 89.3 | H15: 8.6 | I15: 87.6 | J15: 6.5 | K15: 35.2 | L15: 21.2 | M15: 18 | N15: 24.6 | O15: 3.1 | P15: 0.9 | Q15: 51.8 | R15: 73.7 | S15: 11 | T15: Dem | U15: Incumbent | V15: Barbara | W15: Lee | X15: 1998 Special | Y15: Black | Z15: No
A16: California's 14th | B16: CA-14 | C16: Democratic | D16: Eric Swalwell | E16: Democratic | F16: Hold | G16: 71.7 | H16: 26.2 | I16: 70.6 | J16: 23.5 | K16: 28.2 | L16: 22.8 | M16: 6.6 | N16: 40.8 | O16: 2.6 | P16: 1.9 | Q16: 44 | R16: 44.5 | S16: 20.8 | T16: Dem | U16: Incumbent | V16: Eric | W16: Swalwell | X16: 2012 | Y16: White | Z16: No
A17: California's 15th | B17: CA-15 | C17: Democratic | D17: Kevin Mullin | E17: Democratic | F17: Hold | G17: 77.7 | H17: 20.4 | I17: 77.3 | J17: 17.9 | K17: 30.2 | L17: 24.6 | M17: 3.7 | N17: 39.6 | O17: 2.2 | P17: 1.8 | Q17: 46.7 | R17: 59.3 | S17: 14.9 | T17: Dem | U17: Open Seat | V17: Kevin | W17: Mullin | Y17: White | Z17: No
A18: California's 16th | B18: CA-16 | C18: Democratic | D18: Anna Eshoo | E18: Democratic | F18: Hold | G18: 75.4 | H18: 22.4 | I18: 74.4 | J18: 19.6 | K18: 46.3 | L18: 17.4 | M18: 2.8 | N18: 32.1 | O18: 2 | P18: 0.7 | Q18: 60.1 | R18: 68.1 | S18: 17.7 | T18: Dem | U18: Incumbent | V18: Anna | W18: Eshoo | X18: 1992 | Y18: White - Armenian | Z18: No
A19: California's 17th | B19: CA-17 | C19: Democratic | D19: Ro Khanna | E19: Democratic | F19: Hold | G19: 72.7 | H19: 25.3 | I19: 74.1 | J19: 20.2 | K19: 22.8 | L19: 15.1 | M19: 2.7 | N19: 58.5 | O19: 1.6 | P19: 0.8 | Q19: 59.8 | R19: 56.5 | S19: 14.1 | T19: Dem | U19: Incumbent | V19: Ro | W19: Khanna | X19: 2016 | Y19: Asian - Indian | Z19: No
A20: California's 18th | B20: CA-18 | C20: Democratic | D20: Zoe Lofgren | E20: Democratic | F20: Hold | G20: 71 | H20: 26.9 | I20: 71.5 | J20: 22.7 | K20: 21.3 | L20: 60.8 | M20: 3 | N20: 14.3 | O20: 4.9 | P20: 0.7 | Q20: 23.1 | R20: 39.5 | S20: 18.3 | T20: Dem | U20: Incumbent | V20: Zoe | W20: Lofgren | X20: 1994 | Y20: White | Z20: No
A21: California's 19th | B21: CA-19 | C21: Democratic | D21: Jimmy Panetta | E21: Democratic | F21: Hold | G21: 68.7 | H21: 29.1 | I21: 66.4 | J21: 27 | K21: 51.7 | L21: 22 | M21: 3.2 | N21: 20.9 | O21: 3.1 | P21: 0.8 | Q21: 45.2 | R21: 50 | S21: 30 | T21: Dem | U21: Incumbent | V21: Jimmy | W21: Panetta | X21: 2016 | Y21: White | Z21: No
A22: California's 24th | B22: CA-24 | C22: Democratic | D22: Salud Carbajal | E22: Democratic | F22: Hold | G22: 63.3 | H22: 34.3 | I22: 59.1 | J22: 34 | K22: 54.2 | L22: 33.9 | M22: 2.6 | N22: 7.3 | O22: 3.8 | P22: 0.5 | Q22: 36.8 | R22: 47.7 | S22: 33.6 | T22: Dem | U22: Incumbent | V22: Salud | W22: Carbajal | X22: 2016 | Y22: Hispanic - Mexican | Z22: No
A23: California's 25th | B23: CA-25 | C23: Democratic | D23: Raul Ruiz | E23: Democratic | F23: Hold | G23: 56.7 | H23: 41.4 | I23: 56.3 | J23: 38.9 | K23: 28.4 | L23: 60.4 | M23: 5.6 | N23: 4.2 | O23: 4.3 | P23: 0.4 | Q23: 15.9 | R23: 24.1 | S23: 26.9 | T23: Dem | U23: Incumbent | V23: Raul | W23: Ruiz | X23: 2012 | Y23: Hispanic - Mexican | Z23: No
A24: California's 26th | B24: CA-26 | C24: Democratic | D24: Julia Brownley | E24: Democratic | F24: Hold | G24: 58.9 | H24: 39 | I24: 55.7 | J24: 38.4 | K24: 46.2 | L24: 39.1 | M24: 2.7 | N24: 10.6 | O24: 3.4 | P24: 0.5 | Q24: 35.4 | R24: 46.3 | S24: 29.6 | T24: Dem | U24: Incumbent | V24: Julia | W24: Brownley | X24: 2012 | Y24: White | Z24: No
A25: California's 28th | B25: CA-28 | C25: Democratic | D25: Judy Chu | E25: Democratic | F25: Hold | G25: 66.1 | H25: 31.9 | I25: 64.4 | J25: 29.9 | K25: 28.9 | L25: 24.7 | M25: 4.8 | N25: 41.4 | O25: 2.3 | P25: 0.4 | Q25: 45.4 | R25: 56 | S25: 15 | T25: Dem | U25: Incumbent | V25: Judy | W25: Chu | X25: 2009 Special | Y25: Asian - Chinese | Z25: No
A26: California's 29th | B26: CA-29 | C26: Democratic | D26: Tony Cárdenas | E26: Democratic | F26: Hold | G26: 74.5 | H26: 23.2 | I26: 77.9 | J26: 16.6 | K26: 23.6 | L26: 61.1 | M26: 5.2 | N26: 9.8 | O26: 3.7 | P26: 0.3 | Q26: 23.2 | R26: 41.1 | S26: 17.2 | T26: Dem | U26: Incumbent | V26: Tony | W26: Cárdenas | X26: 2012 | Y26: Hispanic - Mexican | Z26: No
A27: California's 30th | B27: CA-30 | C27: Democratic | D27: Adam Schiff | E27: Democratic | F27: Hold | G27: 72.2 | H27: 26 | I27: 73.8 | J27: 20.8 | K27: 57.1 | L27: 21.9 | M27: 4.9 | N27: 15.1 | O27: 2.1 | P27: 0.3 | Q27: 48.1 | R27: 52.9 | S27: 28.7 | T27: Dem | U27: Incumbent | V27: Adam | W27: Schiff | X27: 2000 | Y27: White | Z27: No
A28: California's 31st | B28: CA-31 | C28: Democratic | D28: Grace Napolitano | E28: Democratic | F28: Hold | G28: 64.5 | H28: 33.4 | I28: 65.7 | J28: 28.5 | K28: 16.7 | L28: 57.4 | M28: 3.3 | N28: 22.5 | O28: 3.7 | P28: 0.4 | Q28: 23.6 | R28: 33.9 | S28: 13.6 | T28: Dem | U28: Incumbent | V28: Grace | W28: Napolitano | X28: 1998 | Y28: Hispanic - Mexican | Z28: No
A29: California's 32nd | B29: CA-32 | C29: Democratic | D29: Brad Sherman | E29: Democratic | F29: Hold | G29: 69.5 | H29: 28.7 | I29: 70 | J29: 24.9 | K29: 54.8 | L29: 23.5 | M29: 5.6 | N29: 15.1 | O29: 2 | P29: 0.4 | Q29: 50 | R29: 58.4 | S29: 25.4 | T29: Dem | U29: Incumbent | V29: Brad | W29: Sherman | X29: 1996 | Y29: White | Z29: No
A30: California's 33rd | B30: CA-33 | C30: Democratic | D30: Pete Aguilar | E30: Democratic | F30: Hold | G30: 61.5 | H30: 36.2 | I30: 62.2 | J30: 32.3 | K30: 20.1 | L30: 58.7 | M30: 11.9 | N30: 8.9 | O30: 3.9 | P30: 0.6 | Q30: 19.9 | R30: 28.3 | S30: 18.3 | T30: Dem | U30: Incumbent | V30: Pete | W30: Aguilar | X30: 2014 | Y30: Hispanic - Mexican | Z30: No
A31: California's 35th | B31: CA-35 | C31: Democratic | D31: Norma Torres | E31: Democratic | F31: Hold | G31: 62.7 | H31: 35.1 | I31: 64.6 | J31: 30 | K31: 17 | L31: 61.2 | M31: 7.6 | N31: 13.9 | O31: 3.9 | P31: 0.5 | Q31: 20.7 | R31: 27.8 | S31: 16.4 | T31: Dem | U31: Incumbent | V31: Norma | W31: Torres | X31: 2014 | Y31: Hispanic - Guatemalan | Z31: No
A32: California's 36th | B32: CA-36 | C32: Democratic | D32: Ted Lieu | E32: Democratic | F32: Hold | G32: 71 | H32: 26.9 | I32: 69.2 | J32: 24.8 | K32: 57.5 | L32: 15.5 | M32: 4.8 | N32: 20.5 | O32: 1.8 | P32: 0.5 | Q32: 64.1 | R32: 68.1 | S32: 19.9 | T32: Dem | U32: Incumbent | V32: Ted | W32: Lieu | X32: 2014 | Y32: Asian - Taiwanese | Z32: No
A33: California's 38th | B33: CA-38 | C33: Democratic | D33: Linda Sánchez | E33: Democratic | F33: Hold | G33: 64.1 | H33: 33.9 | I33: 65.2 | J33: 29.3 | K33: 15.1 | L33: 58.3 | M33: 2.7 | N33: 23.8 | O33: 3.6 | P33: 0.5 | Q33: 28.6 | R33: 31.7 | S33: 13.4 | T33: Dem | U33: Incumbent | V33: Linda | W33: Sánchez | X33: 2002 | Y33: Hispanic - Mexican | Z33: No
A34: California's 39th | B34: CA-39 | C34: Democratic | D34: Mark Takano | E34: Democratic | F34: Hold | G34: 62 | H34: 35.8 | I34: 61.4 | J34: 32.7 | K34: 22.4 | L34: 58.5 | M34: 10.4 | N34: 7.9 | O34: 3.9 | P34: 0.7 | Q34: 18.3 | R34: 26.3 | S34: 20.7 | T34: Dem | U34: Incumbent | V34: Mark | W34: Takano | X34: 2012 | Y34: Asian - Japanese | Z34: Gay
A35: California's 42nd | B35: CA-42 | C35: Democratic | D35: Robert Garcia | E35: Democratic | F35: Hold | G35: 71.7 | H35: 25.9 | I35: 72.3 | J35: 21.6 | K35: 20.7 | L35: 61.1 | M35: 7.9 | N35: 9.8 | O35: 4 | P35: 0.7 | Q35: 23.9 | R35: 44.2 | S35: 15.4 | T35: Dem | U35: Open Seat | V35: Robert | W35: Garcia | Y35: Hispanic - Peruvian | Z35: Gay
A36: California's 43rd | B36: CA-43 | C36: Democratic | D36: Maxine Waters | E36: Democratic | F36: Hold | G36: 80.8 | H36: 17 | I36: 84.1 | J36: 11.4 | K36: 8 | L36: 54.1 | M36: 27.4 | N36: 10.6 | O36: 3.5 | P36: 0.7 | Q36: 20 | R36: 41.5 | S36: 6 | T36: Dem | U36: Incumbent | V36: Maxine | W36: Waters | X36: 1990 | Y36: Black | Z36: No
A37: California's 44th | B37: CA-44 | C37: Democratic | D37: Nanette Barragán | E37: Democratic | F37: Hold | G37: 72.9 | H37: 24.7 | I37: 75.6 | J37: 19.1 | K37: 14.4 | L37: 57.9 | M37: 12.8 | N37: 14.2 | O37: 3.9 | P37: 1.4 | Q37: 20.9 | R37: 34.1 | S37: 12.2 | T37: Dem | U37: Incumbent | V37: Nanette | W37: Barragán | X37: 2016 | Y37: Hispanic - Mexican | Z37: No
A38: California's 46th | B38: CA-46 | C38: Democratic | D38: Lou Correa | E38: Democratic | F38: Hold | G38: 64.1 | H38: 33.7 | I38: 66.8 | J38: 27.3 | K38: 17.2 | L38: 61.2 | M38: 2.7 | N38: 18.3 | O38: 4.4 | P38: 0.7 | Q38: 21.2 | R38: 33 | S38: 16.9 | T38: Dem | U38: Incumbent | V38: Lou | W38: Correa | X38: 2016 | Y38: Hispanic - Mexican | Z38: No
A39: California's 50th | B39: CA-50 | C39: Democratic | D39: Scott Peters | E39: Democratic | F39: Hold | G39: 65.4 | H39: 32.2 | I39: 60.5 | J39: 33.2 | K39: 57.9 | L39: 19.6 | M39: 4 | N39: 16.8 | O39: 2.1 | P39: 0.7 | Q39: 57.6 | R39: 63.2 | S39: 24.1 | T39: Dem | U39: Incumbent | V39: Scott | W39: Peters | X39: 2012 | Y39: White | Z39: No
A40: California's 51st | B40: CA-51 | C40: Democratic | D40: Sara Jacobs | E40: Democratic | F40: Hold | G40: 62.5 | H40: 35.2 | I40: 58.4 | J40: 35.4 | K40: 48.6 | L40: 22.6 | M40: 7.5 | N40: 19.9 | O40: 2.5 | P40: 1.1 | Q40: 43 | R40: 47.6 | S40: 29 | T40: Dem | U40: Incumbent | V40: Sara | W40: Jacobs | X40: 2020 | Y40: White | Z40: No
...

Sheet 119th House
A1: Grade (based on USCPR metric) | B1: Rank | C1: First Name | D1: Last Name | E1: CD | F1: Sponsor Score (1/3 of Total Palestine Score) | G1: Total Voting Score (2/3 of Total Palestine Score) | H1: Total Palestine Score ("Present" vote = half of "Yes") | I1: 2026 endorsements | J1: Calling for humanitarian aid for Gaza | K1: UNRWA Funding Emergency Restoration Act | L1: Block the Bombs Act | M1: Recognizing the genocide of the Palestinian people in Gaza | N1: Recognizing the Nakba and Palestinian Refugees’ Rights | O1: United States-Israel Defense Partnership Act | P1: 2027 NDAA that links the US and Israeli military | Q1: State Dept appropriations: $3.3B in military aid for Israel; blocks aid to Palestinian Authority or to support a Palestinian state | R1: Eliminate $3.3 billion in military aid to Israel (Massie amendment) | S1: Final appropriations bill with $3.3B for Israel, $500M for Iron Dome, total ban on UNRWA ICC/ICJ funding, etc. | T1: Appropriations bill increasing funding for military; $3.3B for Israel; defunds USAID and UNRWA | U1: 2026 NDAA with $500 million for U.S.-Israel missile defense cooperation (conference) | V1: [HFAC AMENDMENT] Condition aid to Israel on cooperating with investigations into deaths of U.S. citizens | W1: [HFAC AMENDMENT] Condition aid to Israel on ending war crimes and following international law | X1: Cut $500M for Israeli missile defense programs | Y1: Resolution condemning the Boulder attack that conflates antisemitic violence and anti-Zionism | Z1: Sanction the ICC for Netanyahu warrant | AA1: 2024 NDAA (conference, with Israel funding, anti-Gaza provisions) | AB1: Allow Trump administration to revoke non-profit tax status from pro-Palestine orgs (revote) | AC1: Antisemitism resolution mentioning IHRA definition | AD1: Allow Trump administration to revoke non-profit tax status from pro-Palestine orgs | AE1: Anti-BDS product labeling legislation that rejects the State of Palestine's existence | AF1: Ban State Department from citing Palestinian death tolls from the Gaza Health Ministry | AG1: Sanction the ICC for Netanyahu warrant | AH1: Ban any withholding or reversal of weapons to Israel | AI1: Codify IHRA definition of antisemitism ("anti-zionism is antisemitism") | AJ1: $14 billion in weapons to Israel | AK1: Rules package for Israel/Ukraine/Taiwain aid + Russian/Iran sanctions + TikTok ban | AL1: Resolution standing with Israel against Iran + promising more military aid | AM1: Condemn "from the river to the sea" as antisemitic | AN1: Expanded sanctions on alleged Palestinian use of "human shields" | AO1: Allow Secretary of Treasury to unilaterally designate and terminate tax-exempt status of "terrorist supporting organizations" (targeting pro-Palestine groups) | AP1: Spending bill that cuts UNRWA funding | AQ1: One-sided resolution only condemning Hamas for alleged sexual violence | AR1: $17.6 billion to Israel | AS1: Ban PLO members from entering the U.S. | AT1: Condemning testimony of Harvard, UPenn, MIT's presidents | AU1: Require other countries to disclose "any affiliation" to "terrorist" groups (targeting Palestine) | AV1: IHRA definition of antisemitism + "anti-zionism is antisemitism" | AW1: Declaring that only Hamas's unconditional surrender can save civilian lives | AX1: Affirming Israel's right to exist + denying that right is antisemitism | AY1: Ban funds for colleges with events that violate the pro-Israel IHRA definition of antisemitism | AZ1: Resolution condemning Tlaib saying "from the river to the sea" | BA1: Condemning pro-Palestine college students | BB1: Cut IRS budget for $14 billion in unconditional Israel aid | BC1: Sanction alleged financial backers of Palestinian militant groups | BD1: Meeks/McCaul anti-Palestinian resolution | BE1: Prohibit moving Jerusalem embassy | BF1: Pro-Israel resolution declaring it not a racist or apartheid nation | BG1: Strengthen Abraham Accords with "Special Envoy" position | BH1: Support Abraham Accords | BI1: 2023 NDAA with funding for Israel (conference) | BJ1: Defense spending (with $4.8 billion in weapons to Israel) | BK1: Iron Dome funding | BL1: Unconditional aid to Israel | BM1: Supporting 2016 MOU with Israel | BN1: Anti-BDS resolution | BO1: Pro-Israel resolution criticizing UN's position | BP1: Anti-Palestinian state | BQ1: Letter to ICC complaining about arrest warrant for Netanyahu | BR1: Statement condeming Tlaib saying "from the river to the sea" | BS1: Bipartisan anti-de- escalation letter | BU1: Total Pro-Israel $$$ (negative amount = spending against incumbent) | BV1: AIPAC contributions (direct + bundled from other donors) | BW1: AIPAC's "United Democracy Project" IE spending (for candidate + against opponent) | BX1: DMFI Contributions | BY1: DMFI IE Spending (for candidate + against opponent) | BZ1: JVP- endorsed (2022) | CA1: J Street- endorsed (2022) | CB1: DMFI- endorsed (2022) | CC1: AIPAC- endorsed (2022)
C2: Created and updated by a group of anti-Zionist DSA comrades. | J2: Resolution | K2: Bill | L2: Bill | M2: Resolution | N2: Resolution | O2: Bill | P2: NDAA | Q2: NDAA | R2: Amendment | S2: Bill | T2: Bill | U2: NDAA | V2: Committee vote | W2: Committee vote | X2: Amendment | Y2: Resolution | Z2: Bill | AA2: NDAA | AB2: Bill | AC2: Resolution | AD2: Bill | AE2: Bill | AF2: Bill | AG2: Bill | AH2: Bill | AI2: Bill | AJ2: Bill | AK2: Bill | AL2: Resolution | AM2: Resolution | AN2: Bill | AO2: Bill | AP2: Bill | AQ2: Resolution | AR2: Bill | AS2: Bill | AT2: Resolution | AU2: Bill | AV2: Resolution | AW2: Amendment | AX2: Resolution | AY2: Bill | AZ2: Resolution | BA2: Resolution | BB2: Bill | BC2: Bill | BD2: Resolution | BE2: Bill | BF2: Resolution | BG2: Bill | BH2: Resolution | BI2: NDAA | BJ2: Bill | BK2: Resolution | BL2: Bill | BM2: Resolution | BN2: Resolution | BO2: Resolution | BP2: Resolution
J3: 2025-2027 | K3: 2025-2027 | L3: 2025-2027 | M3: 2025-2027 | N3: 2026-2027 | O3: 2025-2027 | P3: 46225 | Q3: 46218 | R3: 46218 | S3: 46056 | T3: 46036 | U3: 46001 | V3: 45918 | W3: 45918 | X3: 45856 | Y3: 45817 | Z3: 45666 | AA3: 45637 | AB3: 45617 | AC3: 45616 | AD3: 45608 | AE3: 45553 | AF3: 45470 | AG3: 45447 | AH3: 45428 | AI3: 45413 | AJ3: 45402 | AK3: 45401 | AL3: 45399 | AM3: 45398 | AN3: 45398 | AO3: 45397 | AP3: 45373 | AQ3: 45336 | AR3: 45328 | AS3: 45322 | AT3: 45273 | AU3: 45266 | AV3: 45265 | AW3: 45260 | AX3: 45258 | AY3: 45245 | AZ3: 45237 | BA3: 45232 | BB3: 45232 | BC3: 45231 | BD3: 45224 | BE3: 45197 | BF3: 45125 | BG3: 45090 | BH3: 45041 | BI3: 44903 | BJ3: 44629 | BK3: 44462 | BL3: 44405 | BM3: 43805 | BN3: 43669 | BO3: 42740 | BP3: 40731 | BQ3: 45666 | BR3: 45237 | BS3: 45215
H4: % Correct: | J4: =COUNTIF(J5:J243, "Sponsor")/((COUNTIF(J5:J243, "Sponsor")+(COUNTIF(J5:J243, "Not sponsoring")))) -> 0.58490566 | K4: =COUNTIF(K5:K243, "Sponsor")/((COUNTIF(K5:K243, "Sponsor")+(COUNTIF(K5:K243, "Not sponsoring")))) -> 0.36792453 | L4: =COUNTIF(L5:L243, "Sponsor")/((COUNTIF(L5:L243, "Sponsor")+(COUNTIF(L5:L243, "Not sponsoring")))) -> 0.37735849 | M4: =COUNTIF(M5:M243, "Sponsor")/((COUNTIF(M5:M243, "Sponsor")+(COUNTIF(M5:M243, "Not sponsoring")))) -> 0.10377358 | N4: =COUNTIF(N5:N243, "Sponsor")/((COUNTIF(N5:N243, "Sponsor")+(COUNTIF(N5:N243, "Not sponsoring")))) -> 0.066037736 | O4: =COUNTIF(O5:O243, "Not sponsoring (correct)")/((COUNTIF(O5:O243, "Sponsor (incorrect)")+(COUNTIF(O5:O243, "Not sponsoring (correct)")))) -> 0.58962264 | P4: =(COUNTIF(P5:P9080, "No")+COUNTIF(P5:P9080, "Yes (correct)"))/(COUNTIF(P5:P9080, "Yes")+COUNTIF(P5:P9080, "No")+COUNTIF(P5:P9080, "Yes (correct)")+COUNTIF(P5:P9080, "No (incorrect)")) -> 0.97156398 | Q4: =(COUNTIF(Q5:Q9080, "No")+COUNTIF(Q5:Q9080, "Yes (correct)"))/(COUNTIF(Q5:Q9080, "Yes")+COUNTIF(Q5:Q9080, "No")+COUNTIF(Q5:Q9080, "Yes (correct)")+COUNTIF(Q5:Q9080, "No (incorrect)")) -> 0.99521531 | R4: =(COUNTIF(R5:R9080, "No")+COUNTIF(R5:R9080, "Yes (correct)"))/(COUNTIF(R5:R9080, "Yes")+COUNTIF(R5:R9080, "No")+COUNTIF(R5:R9080, "Yes (correct)")+COUNTIF(R5:R9080, "No (incorrect)")) -> 0.51256281 | S4: =(COUNTIF(S5:S9080, "No")+COUNTIF(S5:S9080, "Yes (correct)"))/(COUNTIF(S5:S9080, "Yes")+COUNTIF(S5:S9080, "No")+COUNTIF(S5:S9080, "Yes (correct)")+COUNTIF(S5:S9080, "No (incorrect)")) -> 0.90521327 | T4: =(COUNTIF(T5:T9080, "No")+COUNTIF(T5:T9080, "Yes (correct)"))/(COUNTIF(T5:T9080, "Yes")+COUNTIF(T5:T9080, "No")+COUNTIF(T5:T9080, "Yes (correct)")+COUNTIF(T5:T9080, "No (incorrect)")) -> 0.27536232 | U4: =(COUNTIF(U5:U9080, "No")+COUNTIF(U5:U9080, "Yes (correct)"))/(COUNTIF(U5:U9080, "Yes")+COUNTIF(U5:U9080, "No")+COUNTIF(U5:U9080, "Yes (correct)")+COUNTIF(U5:U9080, "No (incorrect)")) -> 0.45145631 | V4: =(COUNTIF(V5:V9080, "No")+COUNTIF(V5:V9080, "Yes (correct)"))/(COUNTIF(V5:V9080, "Yes")+COUNTIF(V5:V9080, "No")+COUNTIF(V5:V9080, "Yes (correct)")+COUNTIF(V5:V9080, "No (incorrect)")) -> 0.28571429 | W4: =(COUNTIF(W5:W9080, "No")+COUNTIF(W5:W9080, "Yes (correct)"))/(COUNTIF(W5:W9080, "Yes")+COUNTIF(W5:W9080, "No")+COUNTIF(W5:W9080, "Yes (correct)")+COUNTIF(W5:W9080, "No (incorrect)")) -> 0.23809524 | ... BP4: =(COUNTIF(BP5:BP9080, "No")+COUNTIF(BP5:BP9080, "Yes (correct)"))/(COUNTIF(BP5:BP9080, "Yes")+COUNTIF(BP5:BP9080, "No")+COUNTIF(BP5:BP9080, "Yes (correct)")+COUNTIF(BP5:BP9080, "No (incorrect)")) -> 0
A5: =LOOKUP(H5,'Letter grades'!$A$1:$B$6) -> A | B5: =RANK(H5,H:H) -> 1 | C5: Rashida | D5: Tlaib | E5: MI-12 | F5: =((COUNTIF($J5:$BP5,"Sponsor")+COUNTIF($J5:$BP5, "Not sponsoring (correct)"))/(COUNTIF($J5:$BP5,"Sponsor")+COUNTIF($J5:$BP5,"Not sponsoring")+COUNTIF($J5:$BP5, "Not sponsoring (correct)")+COUNTIF($J5:$BP5, "Sponsor (incorrect)"))) -> 1 | G5: =(COUNTIF($K5:$BP5,"No")+COUNTIF($K5:$BP5,"Yes (correct)")+(COUNTIF($K5:$BP5,"Present")*0.5))/(COUNTIF($K5:$BP5,"Yes")+COUNTIF($K5:$BP5,"No")+COUNTIF($K5:$BP5,"Yes (correct)")+COUNTIF($K5:$BP5,"No (incorrect)")+COUNTIF($K5:$BP5,"Present")) -> 0.96875 | H5: =((F5*(1/3))+(G5*(2/3))) -> 0.97916667 | I5: PAL PAC, DSA, JDems | J5: Sponsor | K5: Sponsor | L5: Sponsor | M5: Sponsor | N5: Sponsor | O5: Not sponsoring (correct) | P5: No | Q5: No | R5: Yes (correct) | S5: No | T5: No | U5: No | V5: Not on committee | W5: Not on committee | X5: Yes (correct) | Y5: Present | Z5: No | AA5: No | AB5: No | AC5: No | AD5: No | AE5: No | AF5: No | AG5: Not voting | AH5: No | AI5: No | AJ5: No | AK5: No | AL5: No | AM5: No | AN5: No | AO5: No | AP5: No | AQ5: Present | AR5: No | AS5: No | AT5: No | AU5: No | AV5: No | AW5: No | AX5: Present | AY5: No | AZ5: No | BA5: No | BB5: No | BC5: No | BD5: No | BE5: No | BF5: No | BG5: No | BH5: No | BI5: No | BJ5: No | BK5: No | BL5: No | BM5: No | BN5: No | BO5: Not elected | BP5: Not elected | BQ5: Non-signatory | BR5: Non-signatory | BS5: Non-signatory | BU5: =SUM(BV5:BY5) -> 0 | BZ5: Yes
A6: =LOOKUP(H6,'Letter grades'!$A$1:$B$6) -> A | B6: =RANK(H6,H:H) -> 2 | C6: Ilhan | D6: Omar | E6: MN-05 | F6: =((COUNTIF($J6:$BP6,"Sponsor")+COUNTIF($J6:$BP6, "Not sponsoring (correct)"))/(COUNTIF($J6:$BP6,"Sponsor")+COUNTIF($J6:$BP6,"Not sponsoring")+COUNTIF($J6:$BP6, "Not sponsoring (correct)")+COUNTIF($J6:$BP6, "Sponsor (incorrect)"))) -> 1 | G6: =(COUNTIF($K6:$BP6,"No")+COUNTIF($K6:$BP6,"Yes (correct)")+(COUNTIF($K6:$BP6,"Present")*0.5))/(COUNTIF($K6:$BP6,"Yes")+COUNTIF($K6:$BP6,"No")+COUNTIF($K6:$BP6,"Yes (correct)")+COUNTIF($K6:$BP6,"No (incorrect)")+COUNTIF($K6:$BP6,"Present")) -> 0.91666667 | H6: =((F6*(1/3))+(G6*(2/3))) -> 0.94444444 | I6: PAL PAC, JDems | J6: Sponsor | K6: Sponsor | L6: Sponsor | M6: Sponsor | N6: Sponsor | O6: Not sponsoring (correct) | P6: No | Q6: No | R6: Yes (correct) | S6: No | T6: No | U6: No | V6: Not on committee | W6: Not on committee | X6: Yes (correct) | Y6: Yes | Z6: No | AA6: No | AB6: No | AC6: No | AD6: No | AE6: No | AF6: No | AG6: No | AH6: No | AI6: No | AJ6: No | AK6: No | AL6: No | AM6: No | AN6: No | AO6: No | AP6: No | AQ6: Not voting | AR6: No | AS6: Yes | AT6: No | AU6: No | AV6: No | AW6: No | AX6: Yes | AY6: No | AZ6: No | BA6: No | BB6: No | BC6: No | BD6: No | BE6: No | BF6: No | BG6: No | BH6: No | BI6: No | BJ6: No | BK6: No | BL6: Yes | BM6: No | BN6: No | BO6: Not elected | BP6: Not elected | BQ6: Non-signatory | BR6: Non-signatory | BS6: Non-signatory | BU6: =SUM(BV6:BY6) -> 0 | BZ6: Yes
A7: =LOOKUP(H7,'Letter grades'!$A$1:$B$6) -> A | B7: =RANK(H7,H:H) -> 3 | C7: Delia | D7: Ramirez | E7: IL-03 | F7: =((COUNTIF($J7:$BP7,"Sponsor")+COUNTIF($J7:$BP7, "Not sponsoring (correct)"))/(COUNTIF($J7:$BP7,"Sponsor")+COUNTIF($J7:$BP7,"Not sponsoring")+COUNTIF($J7:$BP7, "Not sponsoring (correct)")+COUNTIF($J7:$BP7, "Sponsor (incorrect)"))) -> 1 | G7: =(COUNTIF($K7:$BP7,"No")+COUNTIF($K7:$BP7,"Yes (correct)")+(COUNTIF($K7:$BP7,"Present")*0.5))/(COUNTIF($K7:$BP7,"Yes")+COUNTIF($K7:$BP7,"No")+COUNTIF($K7:$BP7,"Yes (correct)")+COUNTIF($K7:$BP7,"No (incorrect)")+COUNTIF($K7:$BP7,"Present")) -> 0.86904762 | H7: =((F7*(1/3))+(G7*(2/3))) -> 0.91269841 | I7: PAL PAC, J Street, JDems | J7: Sponsor | K7: Sponsor | L7: Sponsor | M7: Sponsor | N7: Sponsor | O7: Not sponsoring (correct) | P7: No | Q7: No | R7: Yes (correct) | S7: No | T7: No | U7: No | V7: Not on committee | W7: Not on committee | X7: Not voting | Y7: Yes | Z7: No | AA7: No | AB7: No | AC7: Yes | AD7: No | AE7: No | AF7: No | AG7: No | AH7: No | AI7: No | AJ7: No | AK7: No | AL7: No | AM7: No | AN7: Yes | AO7: No | AP7: No | AQ7: Yes | AR7: No | AS7: Present | AT7: No | AU7: No | AV7: No | AW7: No | AX7: Yes | AY7: No | AZ7: No | BA7: No | BB7: No | BC7: No | BD7: No | BE7: No | BF7: No | BG7: No | BH7: No | BI7: Not elected | BJ7: Not elected | BK7: Not elected | BL7: Not elected | BM7: Not elected | BN7: Not elected | BO7: Not elected | BP7: Not elected | BQ7: Non-signatory | BR7: Non-signatory | BS7: Non-signatory | BU7: =SUM(BV7:BY7) -> -157223 | BY7: -157223 | CA7: Yes
A8: =LOOKUP(H8,'Letter grades'!$A$1:$B$6) -> A | B8: =RANK(H8,H:H) -> 4 | C8: Summer | D8: Lee | E8: PA-12 | F8: =((COUNTIF($J8:$BP8,"Sponsor")+COUNTIF($J8:$BP8, "Not sponsoring (correct)"))/(COUNTIF($J8:$BP8,"Sponsor")+COUNTIF($J8:$BP8,"Not sponsoring")+COUNTIF($J8:$BP8, "Not sponsoring (correct)")+COUNTIF($J8:$BP8, "Sponsor (incorrect)"))) -> 1 | G8: =(COUNTIF($K8:$BP8,"No")+COUNTIF($K8:$BP8,"Yes (correct)")+(COUNTIF($K8:$BP8,"Present")*0.5))/(COUNTIF($K8:$BP8,"Yes")+COUNTIF($K8:$BP8,"No")+COUNTIF($K8:$BP8,"Yes (correct)")+COUNTIF($K8:$BP8,"No (incorrect)")+COUNTIF($K8:$BP8,"Present")) -> 0.86046512 | H8: =((F8*(1/3))+(G8*(2/3))) -> 0.90697674 | I8: PAL PAC, JDems | J8: Sponsor | K8: Sponsor | L8: Sponsor | M8: Sponsor | N8: Sponsor | O8: Not sponsoring (correct) | P8: No | Q8: No | R8: Yes (correct) | S8: No | T8: No | U8: No | V8: Not on committee | W8: Not on committee | X8: Yes (correct) | Y8: Yes | Z8: No | AA8: No | AB8: No | AC8: Yes | AD8: No | AE8: No | AF8: No | AG8: No | AH8: No | AI8: No | AJ8: No | AK8: No | AL8: No | AM8: No | AN8: Yes | AO8: No | AP8: No | AQ8: Yes | AR8: No | AS8: Yes | AT8: No | AU8: No | AV8: No | AW8: No | AX8: Yes | AY8: No | AZ8: No | BA8: No | BB8: No | BC8: No | BD8: No | BE8: No | BF8: No | BG8: No | BH8: No | BI8: Not elected | BJ8: Not elected | BK8: Not elected | BL8: Not elected | BM8: Not elected | BN8: Not elected | BO8: Not elected | BP8: Not elected | BQ8: Non-signatory | BR8: Non-signatory | BS8: Non-signatory | BU8: =SUM(BV8:BY8) -> -5099105 | BV8: -699642 | BW8: =-3924473 -> -3924473 | BX8: =-2000 -> -2000 | BY8: -472990 | CA8: Yes
A9: =LOOKUP(H9,'Letter grades'!$A$1:$B$6) -> B | B9: =RANK(H9,H:H) -> 5 | C9: Alexandria | D9: Ocasio-Cortez | E9: NY-14 | F9: =((COUNTIF($J9:$BP9,"Sponsor")+COUNTIF($J9:$BP9, "Not sponsoring (correct)"))/(COUNTIF($J9:$BP9,"Sponsor")+COUNTIF($J9:$BP9,"Not sponsoring")+COUNTIF($J9:$BP9, "Not sponsoring (correct)")+COUNTIF($J9:$BP9, "Sponsor (incorrect)"))) -> 1 | G9: =(COUNTIF($K9:$BP9,"No")+COUNTIF($K9:$BP9,"Yes (correct)")+(COUNTIF($K9:$BP9,"Present")*0.5))/(COUNTIF($K9:$BP9,"Yes")+COUNTIF($K9:$BP9,"No")+COUNTIF($K9:$BP9,"Yes (correct)")+COUNTIF($K9:$BP9,"No (incorrect)")+COUNTIF($K9:$BP9,"Present")) -> 0.84375 | H9: =((F9*(1/3))+(G9*(2/3))) -> 0.89583333 | I9: NYC-DSA, JDems | J9: Sponsor | K9: Sponsor | L9: Sponsor | M9: Sponsor | N9: Sponsor | O9: Not sponsoring (correct) | P9: No | Q9: No | R9: Yes (correct) | S9: No | T9: No | U9: No | V9: Not on committee | W9: Not on committee | X9: No (incorrect) | Y9: Yes | Z9: No | AA9: No | AB9: No | AC9: Yes | AD9: No | AE9: No | AF9: No | AG9: No | AH9: No | AI9: No | AJ9: No | AK9: No | AL9: No | AM9: No | AN9: Yes | AO9: No | AP9: No | AQ9: Yes | AR9: No | AS9: Yes | AT9: No | AU9: No | AV9: No | AW9: Not voting | AX9: Yes | AY9: No | AZ9: No | BA9: No | BB9: No | BC9: No | BD9: No | BE9: No | BF9: No | BG9: No | BH9: No | BI9: No | BJ9: No | BK9: Present | BL9: No | BM9: No | BN9: No | BO9: Not elected | BP9: Not elected | BQ9: Non-signatory | BR9: Non-signatory | BS9: Non-signatory | BU9: =SUM(BV9:BY9) -> 0 | BZ9: Yes
A10: =LOOKUP(H10,'Letter grades'!$A$1:$B$6) -> B | B10: =RANK(H10,H:H) -> 6 | C10: Ayanna | D10: Pressley | E10: MA-07 | F10: =((COUNTIF($J10:$BP10,"Sponsor")+COUNTIF($J10:$BP10, "Not sponsoring (correct)"))/(COUNTIF($J10:$BP10,"Sponsor")+COUNTIF($J10:$BP10,"Not sponsoring")+COUNTIF($J10:$BP10, "Not sponsoring (correct)")+COUNTIF($J10:$BP10, "Sponsor (incorrect)"))) -> 1 | G10: =(COUNTIF($K10:$BP10,"No")+COUNTIF($K10:$BP10,"Yes (correct)")+(COUNTIF($K10:$BP10,"Present")*0.5))/(COUNTIF($K10:$BP10,"Yes")+COUNTIF($K10:$BP10,"No")+COUNTIF($K10:$BP10,"Yes (correct)")+COUNTIF($K10:$BP10,"No (incorrect)")+COUNTIF($K10:$BP10,"Present")) -> 0.80208333 | H10: =((F10*(1/3))+(G10*(2/3))) -> 0.86805556 | I10: JDems | J10: Sponsor | K10: Sponsor | L10: Sponsor | M10: Sponsor | N10: Sponsor | O10: Not sponsoring (correct) | P10: No | Q10: No | R10: Yes (correct) | S10: No | T10: No | U10: No | V10: Not on committee | W10: Not on committee | X10: No (incorrect) | Y10: Yes | Z10: No | AA10: No | AB10: No | AC10: Yes | AD10: No | AE10: No | AF10: No | AG10: No | AH10: No | AI10: No | AJ10: No | AK10: No | AL10: No | AM10: No | AN10: Yes | AO10: No | AP10: Not voting | AQ10: Yes | AR10: No | AS10: Yes | AT10: No | AU10: No | AV10: No | AW10: No | AX10: Yes | AY10: No | AZ10: No | BA10: No | BB10: No | BC10: No | BD10: Present | BE10: No | BF10: No | BG10: No | BH10: No | BI10: No | BJ10: No | BK10: No | BL10: Yes | BM10: No | BN10: Yes | BO10: Not elected | BP10: Not elected | BQ10: Non-signatory | BR10: Non-signatory | BS10: Non-signatory | BU10: =SUM(BV10:BY10) -> 0
A11: =LOOKUP(H11,'Letter grades'!$A$1:$B$6) -> B | B11: =RANK(H11,H:H) -> 7 | C11: Lateefah | D11: Simon | E11: CA-12 | F11: =((COUNTIF($J11:$BP11,"Sponsor")+COUNTIF($J11:$BP11, "Not sponsoring (correct)"))/(COUNTIF($J11:$BP11,"Sponsor")+COUNTIF($J11:$BP11,"Not sponsoring")+COUNTIF($J11:$BP11, "Not sponsoring (correct)")+COUNTIF($J11:$BP11, "Sponsor (incorrect)"))) -> 1 | G11: =(COUNTIF($K11:$BP11,"No")+COUNTIF($K11:$BP11,"Yes (correct)")+(COUNTIF($K11:$BP11,"Present")*0.5))/(COUNTIF($K11:$BP11,"Yes")+COUNTIF($K11:$BP11,"No")+COUNTIF($K11:$BP11,"Yes (correct)")+COUNTIF($K11:$BP11,"No (incorrect)")+COUNTIF($K11:$BP11,"Present")) -> 0.77777778 | H11: =((F11*(1/3))+(G11*(2/3))) -> 0.85185185 | I11: J Street | J11: Sponsor | K11: Sponsor | L11: Sponsor | M11: Sponsor | N11: Sponsor | O11: Not sponsoring (correct) | P11: No | Q11: No | R11: Yes (correct) | S11: No | T11: No | U11: No | V11: Not on committee | W11: Not on committee | X11: No (incorrect) | Y11: Yes | Z11: No | AA11: Not elected | AB11: Not elected | AC11: Not elected | AD11: Not elected | AE11: Not elected | AF11: Not elected | AG11: Not elected | AH11: Not elected | AI11: Not elected | AJ11: Not elected | AK11: Not elected | AL11: Not elected | AM11: Not elected | AN11: Not elected | AO11: Not elected | AP11: Not elected | AQ11: Not elected | AR11: Not elected | AS11: Not elected | AT11: Not elected | AU11: Not elected | AV11: Not elected | AW11: Not elected | AX11: Not elected | AY11: Not elected | AZ11: Not elected | BA11: Not elected | BB11: Not elected | BC11: Not elected | BD11: Not elected | BE11: Not elected | BF11: Not elected | BG11: Not elected | BH11: Not elected | BI11: Not elected | BJ11: Not elected | BK11: Not elected | BL11: Not elected | BM11: Not elected | BN11: Not elected | BO11: Not elected | BP11: Not elected | BQ11: Non-signatory | BR11: Not elected | BS11: Not elected
A12: =LOOKUP(H12,'Letter grades'!$A$1:$B$6) -> B | B12: =RANK(H12,H:H) -> 8 | C12: Jesús "Chuy" | D12: García | E12: IL-04 | F12: =((COUNTIF($J12:$BP12,"Sponsor")+COUNTIF($J12:$BP12, "Not sponsoring (correct)"))/(COUNTIF($J12:$BP12,"Sponsor")+COUNTIF($J12:$BP12,"Not sponsoring")+COUNTIF($J12:$BP12, "Not sponsoring (correct)")+COUNTIF($J12:$BP12, "Sponsor (incorrect)"))) -> 1 | G12: =(COUNTIF($K12:$BP12,"No")+COUNTIF($K12:$BP12,"Yes (correct)")+(COUNTIF($K12:$BP12,"Present")*0.5))/(COUNTIF($K12:$BP12,"Yes")+COUNTIF($K12:$BP12,"No")+COUNTIF($K12:$BP12,"Yes (correct)")+COUNTIF($K12:$BP12,"No (incorrect)")+COUNTIF($K12:$BP12,"Present")) -> 0.7755102 | H12: =((F12*(1/3))+(G12*(2/3))) -> 0.85034014 | I12: J Street | J12: Sponsor | K12: Sponsor | L12: Sponsor | M12: Sponsor | N12: Sponsor | O12: Not sponsoring (correct) | P12: No | Q12: No | R12: Yes (correct) | S12: No | T12: No | U12: No | V12: Not on committee | W12: Not on committee | X12: No (incorrect) | Y12: Yes | Z12: No | AA12: No | AB12: No | AC12: Yes | AD12: No | AE12: No | AF12: No | AG12: No | AH12: No | AI12: No | AJ12: No | AK12: No | AL12: Yes | AM12: No | AN12: Yes | AO12: No | AP12: No | AQ12: Yes | AR12: No | AS12: Yes | AT12: No | AU12: No | AV12: No | AW12: No | AX12: Yes | AY12: No | AZ12: No | BA12: No | BB12: No | BC12: No | BD12: Present | BE12: No | BF12: Yes | BG12: No | BH12: No | BI12: No | BJ12: No | BK12: No | BL12: Yes | BM12: Present | BN12: No | BO12: Not elected | BP12: Not elected | BQ12: Non-signatory | BR12: Non-signatory | BS12: Non-signatory | BU12: =SUM(BV12:BY12) -> 0 | BZ12: Yes | CA12: Yes
A13: =LOOKUP(H13,'Letter grades'!$A$1:$B$6) -> C | B13: =RANK(H13,H:H) -> 9 | C13: Maxine | D13: Dexter | E13: OR-03 | F13: =((COUNTIF($J13:$BP13,"Sponsor")+COUNTIF($J13:$BP13, "Not sponsoring (correct)"))/(COUNTIF($J13:$BP13,"Sponsor")+COUNTIF($J13:$BP13,"Not sponsoring")+COUNTIF($J13:$BP13, "Not sponsoring (correct)")+COUNTIF($J13:$BP13, "Sponsor (incorrect)"))) -> 0.83333333 | G13: =(COUNTIF($K13:$BP13,"No")+COUNTIF($K13:$BP13,"Yes (correct)")+(COUNTIF($K13:$BP13,"Present")*0.5))/(COUNTIF($K13:$BP13,"Yes")+COUNTIF($K13:$BP13,"No")+COUNTIF($K13:$BP13,"Yes (correct)")+COUNTIF($K13:$BP13,"No (incorrect)")+COUNTIF($K13:$BP13,"Present")) -> 0.77777778 | H13: =((F13*(1/3))+(G13*(2/3))) -> 0.7962963 | J13: Sponsor | K13: Sponsor | L13: Sponsor | M13: Sponsor | N13: Not sponsoring | O13: Not sponsoring (correct) | P13: No | Q13: No | R13: Yes (correct) | S13: No | T13: No | U13: No | V13: Not on committee | W13: Not on committee | X13: No (incorrect) | Y13: Yes | Z13: No | AA13: Not elected | AB13: Not elected | AC13: Not elected | AD13: Not elected | AE13: Not elected | AF13: Not elected | AG13: Not elected | AH13: Not elected | AI13: Not elected | AJ13: Not elected | AK13: Not elected | AL13: Not elected | AM13: Not elected | AN13: Not elected | AO13: Not elected | AP13: Not elected | AQ13: Not elected | AR13: Not elected | AS13: Not elected | AT13: Not elected | AU13: Not elected | AV13: Not elected | AW13: Not elected | AX13: Not elected | AY13: Not elected | AZ13: Not elected | BA13: Not elected | BB13: Not elected | BC13: Not elected | BD13: Not elected | BE13: Not elected | BF13: Not elected | BG13: Not elected | BH13: Not elected | BI13: Not elected | BJ13: Not elected | BK13: Not elected | BL13: Not elected | BM13: Not elected | BN13: Not elected | BO13: Not elected | BP13: Not elected | BQ13: Non-signatory | BR13: Not elected | BS13: Not elected
A14: =LOOKUP(H14,'Letter grades'!$A$1:$B$6) -> C | B14: =RANK(H14,H:H) -> 10 | C14: Adelita | D14: Grijalva | E14: AZ-07 | F14: =((COUNTIF($J14:$BP14,"Sponsor")+COUNTIF($J14:$BP14, "Not sponsoring (correct)"))/(COUNTIF($J14:$BP14,"Sponsor")+COUNTIF($J14:$BP14,"Not sponsoring")+COUNTIF($J14:$BP14, "Not sponsoring (correct)")+COUNTIF($J14:$BP14, "Sponsor (incorrect)"))) -> 0.33333333 | G14: =(COUNTIF($K14:$BP14,"No")+COUNTIF($K14:$BP14,"Yes (correct)")+(COUNTIF($K14:$BP14,"Present")*0.5))/(COUNTIF($K14:$BP14,"Yes")+COUNTIF($K14:$BP14,"No")+COUNTIF($K14:$BP14,"Yes (correct)")+COUNTIF($K14:$BP14,"No (incorrect)")+COUNTIF($K14:$BP14,"Present")) -> 1 | H14: =((F14*(1/3))+(G14*(2/3))) -> 0.77777778 | I14: J Street | J14: Not sponsoring | K14: Not sponsoring | L14: Sponsor | M14: Not sponsoring | N14: Not sponsoring | O14: Not sponsoring (correct) | P14: No | Q14: No | R14: Yes (correct) | S14: No | T14: No | U14: No | V14: Not elected | W14: Not elected | X14: Not elected | Y14: Not elected | Z14: Not elected | AA14: Not elected | AB14: Not elected | AC14: Not elected | AD14: Not elected | AE14: Not elected | AF14: Not elected | AG14: Not elected | AH14: Not elected | AI14: Not elected | AJ14: Not elected | AK14: Not elected | AL14: Not elected | AM14: Not elected | AN14: Not elected | AO14: Not elected | AP14: Not elected | AQ14: Not elected | AR14: Not elected | AS14: Not elected | AT14: Not elected | AU14: Not elected | AV14: Not elected | AW14: Not elected | AX14: Not elected | AY14: Not elected | AZ14: Not elected | BA14: Not elected | BB14: Not elected | BC14: Not elected | BD14: Not elected | BE14: Not elected | BF14: Not elected | BG14: Not elected | BH14: Not elected | BI14: Not elected | BJ14: Not elected | BK14: Not elected | BL14: Not elected | BM14: Not elected | BN14: Not elected | BO14: Not elected | BP14: Not elected | BQ14: Not elected | BR14: Not elected | BS14: Not elected
A15: =LOOKUP(H15,'Letter grades'!$A$1:$B$6) -> C | B15: =RANK(H15,H:H) -> 11 | C15: André | D15: Carson | E15: IN-07 | F15: =((COUNTIF($J15:$BP15,"Sponsor")+COUNTIF($J15:$BP15, "Not sponsoring (correct)"))/(COUNTIF($J15:$BP15,"Sponsor")+COUNTIF($J15:$BP15,"Not sponsoring")+COUNTIF($J15:$BP15, "Not sponsoring (correct)")+COUNTIF($J15:$BP15, "Sponsor (incorrect)"))) -> 1 | G15: =(COUNTIF($K15:$BP15,"No")+COUNTIF($K15:$BP15,"Yes (correct)")+(COUNTIF($K15:$BP15,"Present")*0.5))/(COUNTIF($K15:$BP15,"Yes")+COUNTIF($K15:$BP15,"No")+COUNTIF($K15:$BP15,"Yes (correct)")+COUNTIF($K15:$BP15,"No (incorrect)")+COUNTIF($K15:$BP15,"Present")) -> 0.66 | H15: =((F15*(1/3))+(G15*(2/3))) -> 0.77333333 | I15: J Street | J15: Sponsor | K15: Sponsor | L15: Sponsor | M15: Sponsor | N15: Sponsor | O15: Not sponsoring (correct) | P15: No | Q15: No | R15: Yes (correct) | S15: No | T15: No | U15: No | V15: Not on committee | W15: Not on committee | X15: No (incorrect) | Y15: Yes | Z15: No | AA15: No | AB15: No | AC15: Yes | AD15: No | AE15: No | AF15: No | AG15: No | AH15: Not voting | AI15: No | AJ15: No | AK15: No | AL15: Yes | AM15: No | AN15: Yes | AO15: Yes | AP15: No | AQ15: Yes | AR15: No | AS15: Yes | AT15: No | AU15: No | AV15: Present | AW15: Yes | AX15: Yes | AY15: Yes | AZ15: No | BA15: No | BB15: No | BC15: No | BD15: No | BE15: No | BF15: No | BG15: Yes | BH15: No | BI15: Yes | BJ15: Yes | BK15: No | BL15: Yes | BM15: Yes | BN15: No | BO15: No | BP15: Present | BQ15: Non-signatory | BR15: Non-signatory | BS15: Non-signatory | BU15: =SUM(BV15:BY15) -> 0 | BZ15: Yes | CA15: Yes
A16: =LOOKUP(H16,'Letter grades'!$A$1:$B$6) -> C | B16: =RANK(H16,H:H) -> 12 | C16: Pramila | D16: Jayapal | E16: WA-07 | F16: =((COUNTIF($J16:$BP16,"Sponsor")+COUNTIF($J16:$BP16, "Not sponsoring (correct)"))/(COUNTIF($J16:$BP16,"Sponsor")+COUNTIF($J16:$BP16,"Not sponsoring")+COUNTIF($J16:$BP16, "Not sponsoring (correct)")+COUNTIF($J16:$BP16, "Sponsor (incorrect)"))) -> 0.83333333 | G16: =(COUNTIF($K16:$BP16,"No")+COUNTIF($K16:$BP16,"Yes (correct)")+(COUNTIF($K16:$BP16,"Present")*0.5))/(COUNTIF($K16:$BP16,"Yes")+COUNTIF($K16:$BP16,"No")+COUNTIF($K16:$BP16,"Yes (correct)")+COUNTIF($K16:$BP16,"No (incorrect)")+COUNTIF($K16:$BP16,"Present")) -> 0.72115385 | H16: =((F16*(1/3))+(G16*(2/3))) -> 0.75854701 | I16: J Street, JDems | J16: Sponsor | K16: Sponsor | L16: Sponsor | M16: Sponsor | N16: Not sponsoring | O16: Not sponsoring (correct) | P16: No | Q16: No | R16: Yes (correct) | S16: No | T16: No | U16: No | V16: Yes (correct) | W16: Yes (correct) | X16: No (incorrect) | Y16: Yes | Z16: No | AA16: No | AB16: No | AC16: Yes | AD16: No | AE16: No | AF16: No | AG16: No | AH16: No | AI16: No | AJ16: No | AK16: No | AL16: No | AM16: No | AN16: Yes | AO16: Yes | AP16: No | AQ16: Yes | AR16: No | AS16: Yes | AT16: No | AU16: No | AV16: No | AW16: Yes | AX16: Yes | AY16: No | AZ16: No | BA16: No | BB16: No | BC16: No | BD16: Present | BE16: No | BF16: Yes | BG16: Yes | BH16: No | BI16: No | BJ16: No | BK16: Yes | BL16: Yes | BM16: Yes | BN16: No | BO16: No | BP16: Not elected | BQ16: Non-signatory | BR16: Non-signatory | BS16: Non-signatory | BU16: =SUM(BV16:BY16) -> 0 | BZ16: Yes | CA16: Yes
A17: =LOOKUP(H17,'Letter grades'!$A$1:$B$6) -> C | B17: =RANK(H17,H:H) -> 13 | C17: Greg | D17: Casar | E17: TX-35 | F17: =((COUNTIF($J17:$BP17,"Sponsor")+COUNTIF($J17:$BP17, "Not sponsoring (correct)"))/(COUNTIF($J17:$BP17,"Sponsor")+COUNTIF($J17:$BP17,"Not sponsoring")+COUNTIF($J17:$BP17, "Not sponsoring (correct)")+COUNTIF($J17:$BP17, "Sponsor (incorrect)"))) -> 0.83333333 | G17: =(COUNTIF($K17:$BP17,"No")+COUNTIF($K17:$BP17,"Yes (correct)")+(COUNTIF($K17:$BP17,"Present")*0.5))/(COUNTIF($K17:$BP17,"Yes")+COUNTIF($K17:$BP17,"No")+COUNTIF($K17:$BP17,"Yes (correct)")+COUNTIF($K17:$BP17,"No (incorrect)")+COUNTIF($K17:$BP17,"Present")) -> 0.69047619 | H17: =((F17*(1/3))+(G17*(2/3))) -> 0.73809524 | I17: J Street, JDems | J17: Sponsor | K17: Sponsor | L17: Sponsor | M17: Sponsor | N17: Not sponsoring | O17: Not sponsoring (correct) | P17: No | Q17: No | R17: Yes (correct) | S17: No | T17: Not voting | U17: No | V17: Not on committee | W17: Not on committee | X17: No (incorrect) | Y17: Yes | Z17: No | AA17: No | AB17: No | AC17: Yes | AD17: No | AE17: No | AF17: No | AG17: No | AH17: No | AI17: No | AJ17: No | AK17: No | AL17: No | AM17: No | AN17: Yes | AO17: Yes | AP17: No | AQ17: Yes | AR17: No | AS17: Yes | AT17: No | AU17: No | AV17: Present | AW17: No | AX17: Yes | AY17: No | AZ17: No | BA17: Yes | BB17: No | BC17: No | BD17: Present | BE17: No | BF17: Yes | BG17: Yes | BH17: Yes | BI17: Not elected | BJ17: Not elected | BK17: Not elected | BL17: Not elected | BM17: Not elected | BN17: Not elected | BO17: Not elected | BP17: Not elected | BQ17: Non-signatory | BR17: Non-signatory | BS17: Non-signatory | BU17: =SUM(BV17:BY17) -> 0 | CA17: Yes
A18: =LOOKUP(H18,'Letter grades'!$A$1:$B$6) -> C | B18: =RANK(H18,H:H) -> 14 | C18: Bonnie | D18: Watson Coleman | E18: NJ-12 | F18: =((COUNTIF($J18:$BP18,"Sponsor")+COUNTIF($J18:$BP18, "Not sponsoring (correct)"))/(COUNTIF($J18:$BP18,"Sponsor")+COUNTIF($J18:$BP18,"Not sponsoring")+COUNTIF($J18:$BP18, "Not sponsoring (correct)")+COUNTIF($J18:$BP18, "Sponsor (incorrect)"))) -> 1 | G18: =(COUNTIF($K18:$BP18,"No")+COUNTIF($K18:$BP18,"Yes (correct)")+(COUNTIF($K18:$BP18,"Present")*0.5))/(COUNTIF($K18:$BP18,"Yes")+COUNTIF($K18:$BP18,"No")+COUNTIF($K18:$BP18,"Yes (correct)")+COUNTIF($K18:$BP18,"No (incorrect)")+COUNTIF($K18:$BP18,"Present")) -> 0.59574468 | H18: =((F18*(1/3))+(G18*(2/3))) -> 0.73049645 | I18: J Street | J18: Sponsor | K18: Sponsor | L18: Sponsor | M18: Sponsor | N18: Sponsor | O18: Not sponsoring (correct) | P18: No | Q18: No | R18: Yes (correct) | S18: No | T18: No | U18: No | V18: Not on committee | W18: Not on committee | X18: No (incorrect) | Y18: Yes | Z18: No | AA18: No | AB18: No | AC18: Yes | AD18: No | AE18: No | AF18: Not voting | AG18: Not voting | AH18: No | AI18: No | AJ18: No | AK18: No | AL18: Yes | AM18: No | AN18: Yes | AO18: Yes | AP18: Yes | AQ18: Yes | AR18: No | AS18: Yes | AT18: No | AU18: No | AV18: No | AW18: Yes | AX18: Yes | AY18: No | AZ18: No | BA18: No | BB18: No | BC18: Yes | BD18: Yes | BE18: Yes | BF18: Yes | BG18: Yes | BH18: Not voting | BI18: No | BJ18: No | BK18: Yes | BL18: Yes | BM18: Yes | BN18: No | BO18: No | BP18: Not elected | BQ18: Non-signatory | BR18: Non-signatory | BS18: Non-signatory | BU18: =SUM(BV18:BY18) -> 0 | CA18: Yes
A19: =LOOKUP(H19,'Letter grades'!$A$1:$B$6) -> C | B19: =RANK(H19,H:H) -> 15 | C19: Maxwell | D19: Frost | E19: FL-10 | F19: =((COUNTIF($J19:$BP19,"Sponsor")+COUNTIF($J19:$BP19, "Not sponsoring (correct)"))/(COUNTIF($J19:$BP19,"Sponsor")+COUNTIF($J19:$BP19,"Not sponsoring")+COUNTIF($J19:$BP19, "Not sponsoring (correct)")+COUNTIF($J19:$BP19, "Sponsor (incorrect)"))) -> 0.83333333 | G19: =(COUNTIF($K19:$BP19,"No")+COUNTIF($K19:$BP19,"Yes (correct)")+(COUNTIF($K19:$BP19,"Present")*0.5))/(COUNTIF($K19:$BP19,"Yes")+COUNTIF($K19:$BP19,"No")+COUNTIF($K19:$BP19,"Yes (correct)")+COUNTIF($K19:$BP19,"No (incorrect)")+COUNTIF($K19:$BP19,"Present")) -> 0.62790698 | H19: =((F19*(1/3))+(G19*(2/3))) -> 0.69638243 | J19: Sponsor | K19: Sponsor | L19: Sponsor | M19: Sponsor | N19: Not sponsoring | O19: Not sponsoring (correct) | P19: No | Q19: No | R19: Yes (correct) | S19: No | T19: No | U19: No | V19: Not on committee | W19: Not on committee | X19: No (incorrect) | Y19: Yes | Z19: No | AA19: No | AB19: No | AC19: Yes | AD19: No | AE19: No | AF19: No | AG19: No | AH19: No | AI19: No | AJ19: No | AK19: No | AL19: Yes | AM19: No | AN19: Yes | AO19: Yes | AP19: No | AQ19: Yes | AR19: No | AS19: Yes | AT19: No | AU19: No | AV19: Yes | AW19: Yes | AX19: Yes | AY19: Yes | AZ19: No | BA19: No | BB19: No | BC19: No | BD19: Yes | BE19: No | BF19: Yes | BG19: Yes | BH19: Yes | BI19: Not elected | BJ19: Not elected | BK19: Not elected | BL19: Not elected | BM19: Not elected | BN19: Not elected | BO19: Not elected | BP19: Not elected | BQ19: Non-signatory | BR19: Non-signatory | BS19: Non-signatory | BU19: =SUM(BV19:BY19) -> 0
A20: =LOOKUP(H20,'Letter grades'!$A$1:$B$6) -> C | B20: =RANK(H20,H:H) -> 16 | C20: Mark | D20: Pocan | E20: WI-02 | F20: =((COUNTIF($J20:$BP20,"Sponsor")+COUNTIF($J20:$BP20, "Not sponsoring (correct)"))/(COUNTIF($J20:$BP20,"Sponsor")+COUNTIF($J20:$BP20,"Not sponsoring")+COUNTIF($J20:$BP20, "Not sponsoring (correct)")+COUNTIF($J20:$BP20, "Sponsor (incorrect)"))) -> 0.83333333 | G20: =(COUNTIF($K20:$BP20,"No")+COUNTIF($K20:$BP20,"Yes (correct)")+(COUNTIF($K20:$BP20,"Present")*0.5))/(COUNTIF($K20:$BP20,"Yes")+COUNTIF($K20:$BP20,"No")+COUNTIF($K20:$BP20,"Yes (correct)")+COUNTIF($K20:$BP20,"No (incorrect)")+COUNTIF($K20:$BP20,"Present")) -> 0.62244898 | H20: =((F20*(1/3))+(G20*(2/3))) -> 0.69274376 | I20: J Street | J20: Sponsor | K20: Sponsor | L20: Sponsor | M20: Sponsor | N20: Not sponsoring | O20: Not sponsoring (correct) | P20: No | Q20: No | R20: Yes (correct) | S20: No | T20: No | U20: No | V20: Not on committee | W20: Not on committee | X20: No (incorrect) | Y20: Yes | Z20: No | AA20: No | AB20: No | AC20: Yes | AD20: No | AE20: No | AF20: Not voting | AG20: No | AH20: No | AI20: No | AJ20: No | AK20: No | AL20: Yes | AM20: No | AN20: Yes | AO20: Yes | AP20: Yes | AQ20: Yes | AR20: No | AS20: Yes | AT20: No | AU20: No | AV20: Present | AW20: Yes | AX20: Yes | AY20: No | AZ20: No | BA20: Yes | BB20: No | BC20: No | BD20: Yes | BE20: No | BF20: Yes | BG20: Yes | BH20: No | BI20: No | BJ20: No | BK20: Yes | BL20: Yes | BM20: Yes | BN20: No | BO20: No | BP20: Not elected | BQ20: Non-signatory | BR20: Non-signatory | BS20: Non-signatory | BU20: =SUM(BV20:BY20) -> 0 | BZ20: Yes | CA20: Yes
A21: =LOOKUP(H21,'Letter grades'!$A$1:$B$6) -> C | B21: =RANK(H21,H:H) -> 17 | C21: Hank | D21: Johnson | E21: GA-04 | F21: =((COUNTIF($J21:$BP21,"Sponsor")+COUNTIF($J21:$BP21, "Not sponsoring (correct)"))/(COUNTIF($J21:$BP21,"Sponsor")+COUNTIF($J21:$BP21,"Not sponsoring")+COUNTIF($J21:$BP21, "Not sponsoring (correct)")+COUNTIF($J21:$BP21, "Sponsor (incorrect)"))) -> 1 | G21: =(COUNTIF($K21:$BP21,"No")+COUNTIF($K21:$BP21,"Yes (correct)")+(COUNTIF($K21:$BP21,"Present")*0.5))/(COUNTIF($K21:$BP21,"Yes")+COUNTIF($K21:$BP21,"No")+COUNTIF($K21:$BP21,"Yes (correct)")+COUNTIF($K21:$BP21,"No (incorrect)")+COUNTIF($K21:$BP21,"Present")) -> 0.53 | H21: =((F21*(1/3))+(G21*(2/3))) -> 0.68666667 | I21: J Street | J21: Sponsor | K21: Sponsor | L21: Sponsor | M21: Sponsor | N21: Sponsor | O21: Not sponsoring (correct) | P21: No | Q21: No | R21: Yes (correct) | S21: No | T21: Yes | U21: No | V21: Not on committee | W21: Not on committee | X21: No (incorrect) | Y21: Yes | Z21: No | AA21: No | AB21: No | AC21: Yes | AD21: No | AE21: No | AF21: No | AG21: No | AH21: No | AI21: No | AJ21: No | AK21: Yes | AL21: No | AM21: No | AN21: Yes | AO21: Yes | AP21: Yes | AQ21: Yes | AR21: No | AS21: Yes | AT21: No | AU21: Not voting | AV21: Present | AW21: Yes | AX21: Yes | AY21: No | AZ21: No | BA21: Yes | BB21: No | BC21: Yes | BD21: Yes | BE21: No | BF21: Yes | BG21: Yes | BH21: No | BI21: Yes | BJ21: Yes | BK21: Present | BL21: Yes | BM21: Yes | BN21: Present | BO21: No | BP21: Yes | BQ21: Non-signatory | BR21: Non-signatory | BS21: Non-signatory | BU21: =SUM(BV21:BY21) -> 0 | CA21: Yes
A22: =LOOKUP(H22,'Letter grades'!$A$1:$B$6) -> C | B22: =RANK(H22,H:H) -> 18 | C22: Emily | D22: Randall | E22: WA-06 | F22: =((COUNTIF($J22:$BP22,"Sponsor")+COUNTIF($J22:$BP22, "Not sponsoring (correct)"))/(COUNTIF($J22:$BP22,"Sponsor")+COUNTIF($J22:$BP22,"Not sponsoring")+COUNTIF($J22:$BP22, "Not sponsoring (correct)")+COUNTIF($J22:$BP22, "Sponsor (incorrect)"))) -> 0.5 | G22: =(COUNTIF($K22:$BP22,"No")+COUNTIF($K22:$BP22,"Yes (correct)")+(COUNTIF($K22:$BP22,"Present")*0.5))/(COUNTIF($K22:$BP22,"Yes")+COUNTIF($K22:$BP22,"No")+COUNTIF($K22:$BP22,"Yes (correct)")+COUNTIF($K22:$BP22,"No (incorrect)")+COUNTIF($K22:$BP22,"Present")) -> 0.77777778 | H22: =((F22*(1/3))+(G22*(2/3))) -> 0.68518519 | I22: J Street | J22: Sponsor | K22: Sponsor | L22: Not sponsoring | M22: Not sponsoring | N22: Not sponsoring | O22: Not sponsoring (correct) | P22: No | Q22: No | R22: Yes (correct) | S22: No | T22: No | U22: No | V22: Not on committee | W22: Not on committee | X22: No (incorrect) | Y22: Yes | Z22: No | AA22: Not elected | AB22: Not elected | AC22: Not elected | AD22: Not elected | AE22: Not elected | AF22: Not elected | AG22: Not elected | AH22: Not elected | AI22: Not elected | AJ22: Not elected | AK22: Not elected | AL22: Not elected | AM22: Not elected | AN22: Not elected | AO22: Not elected | AP22: Not elected | AQ22: Not elected | AR22: Not elected | AS22: Not elected | AT22: Not elected | AU22: Not elected | AV22: Not elected | AW22: Not elected | AX22: Not elected | AY22: Not elected | AZ22: Not elected | BA22: Not elected | BB22: Not elected | BC22: Not elected | BD22: Not elected | BE22: Not elected | BF22: Not elected | BG22: Not elected | BH22: Not elected | BI22: Not elected | BJ22: Not elected | BK22: Not elected | BL22: Not elected | BM22: Not elected | BN22: Not elected | BO22: Not elected | BP22: Not elected | BQ22: Non-signatory | BR22: Not elected | BS22: Not elected
A23: =LOOKUP(H23,'Letter grades'!$A$1:$B$6) -> C | B23: =RANK(H23,H:H) -> 19 | C23: Becca | D23: Balint | E23: VT-AL | F23: =((COUNTIF($J23:$BP23,"Sponsor")+COUNTIF($J23:$BP23, "Not sponsoring (correct)"))/(COUNTIF($J23:$BP23,"Sponsor")+COUNTIF($J23:$BP23,"Not sponsoring")+COUNTIF($J23:$BP23, "Not sponsoring (correct)")+COUNTIF($J23:$BP23, "Sponsor (incorrect)"))) -> 0.83333333 | G23: =(COUNTIF($K23:$BP23,"No")+COUNTIF($K23:$BP23,"Yes (correct)")+(COUNTIF($K23:$BP23,"Present")*0.5))/(COUNTIF($K23:$BP23,"Yes")+COUNTIF($K23:$BP23,"No")+COUNTIF($K23:$BP23,"Yes (correct)")+COUNTIF($K23:$BP23,"No (incorrect)")+COUNTIF($K23:$BP23,"Present")) -> 0.60714286 | H23: =((F23*(1/3))+(G23*(2/3))) -> 0.68253968 | I23: J Street | J23: Sponsor | K23: Sponsor | L23: Sponsor | M23: Sponsor | N23: Not sponsoring | O23: Not sponsoring (correct) | P23: No | Q23: No | R23: Yes (correct) | S23: No | T23: No | U23: No | V23: Not on committee | W23: Not on committee | X23: No (incorrect) | Y23: Yes | Z23: No | AA23: No | AB23: No | AC23: Yes | AD23: No | AE23: No | AF23: No | AG23: No | AH23: No | AI23: No | AJ23: No | AK23: No | AL23: Yes | AM23: No | AN23: Yes | AO23: Yes | AP23: No | AQ23: Yes | AR23: No | AS23: Yes | AT23: No | AU23: Not voting | AV23: Present | AW23: Yes | AX23: Yes | AY23: No | AZ23: No | BA23: Yes | BB23: No | BC23: No | BD23: Yes | BE23: Yes | BF23: Yes | BG23: Yes | BH23: Yes | BI23: Not elected | BJ23: Not elected | BK23: Not elected | BL23: Not elected | BM23: Not elected | BN23: Not elected | BO23: Not elected | BP23: Not elected | BQ23: Non-signatory | BR23: Non-signatory | BS23: Non-signatory | BU23: =SUM(BV23:BY23) -> 0 | CA23: Yes
A24: =LOOKUP(H24,'Letter grades'!$A$1:$B$6) -> C | B24: =RANK(H24,H:H) -> 20 | C24: LaMonica | D24: McIver | E24: NJ-10 | F24: =((COUNTIF($J24:$BP24,"Sponsor")+COUNTIF($J24:$BP24, "Not sponsoring (correct)"))/(COUNTIF($J24:$BP24,"Sponsor")+COUNTIF($J24:$BP24,"Not sponsoring")+COUNTIF($J24:$BP24, "Not sponsoring (correct)")+COUNTIF($J24:$BP24, "Sponsor (incorrect)"))) -> 0.5 | G24: =(COUNTIF($K24:$BP24,"No")+COUNTIF($K24:$BP24,"Yes (correct)")+(COUNTIF($K24:$BP24,"Present")*0.5))/(COUNTIF($K24:$BP24,"Yes")+COUNTIF($K24:$BP24,"No")+COUNTIF($K24:$BP24,"Yes (correct)")+COUNTIF($K24:$BP24,"No (incorrect)")+COUNTIF($K24:$BP24,"Present")) -> 0.76923077 | H24: =((F24*(1/3))+(G24*(2/3))) -> 0.67948718 | J24: Sponsor | K24: Not sponsoring | L24: Sponsor | M24: Not sponsoring | N24: Not sponsoring | O24: Not sponsoring (correct) | P24: No | Q24: No | R24: Yes (correct) | S24: No | T24: No | U24: No | V24: Not on committee | W24: Not on committee | X24: No (incorrect) | Y24: Yes | Z24: No | AA24: No | AB24: No | AC24: Yes | AD24: No | AE24: Not elected | AF24: Not elected | AG24: Not elected | AH24: Not elected | AI24: Not elected | AJ24: Not elected | AK24: Not elected | AL24: Not elected | AM24: Not elected | AN24: Not elected | AO24: Not elected | AP24: Not elected | AQ24: Not elected | AR24: Not elected | AS24: Not elected | AT24: Not elected | AU24: Not elected | AV24: Not elected | AW24: Not elected | AX24: Not elected | AY24: Not elected | AZ24: Not elected | BA24: Not elected | BB24: Not elected | BC24: Not elected | BD24: Not elected | BE24: Not elected | BF24: Not elected | BG24: Not elected | BH24: Not elected | BI24: Not elected | BJ24: Not elected | BK24: Not elected | BL24: Not elected | BM24: Not elected | BN24: Not elected | BO24: Not elected | BP24: Not elected | BQ24: Non-signatory | BR24: Not elected | BS24: Not elected | BU24: Not elected | BV24: Not elected | BW24: Not elected | BX24: Not elected | BY24: Not elected | BZ24: Not elected | CA24: Not elected | CB24: Not elected | CC24: Not elected
A25: =LOOKUP(H25,'Letter grades'!$A$1:$B$6) -> C | B25: =RANK(H25,H:H) -> 21 | C25: Al | D25: Green | E25: TX-09 | F25: =((COUNTIF($J25:$BP25,"Sponsor")+COUNTIF($J25:$BP25, "Not sponsoring (correct)"))/(COUNTIF($J25:$BP25,"Sponsor")+COUNTIF($J25:$BP25,"Not sponsoring")+COUNTIF($J25:$BP25, "Not sponsoring (correct)")+COUNTIF($J25:$BP25, "Sponsor (incorrect)"))) -> 1 | G25: =(COUNTIF($K25:$BP25,"No")+COUNTIF($K25:$BP25,"Yes (correct)")+(COUNTIF($K25:$BP25,"Present")*0.5))/(COUNTIF($K25:$BP25,"Yes")+COUNTIF($K25:$BP25,"No")+COUNTIF($K25:$BP25,"Yes (correct)")+COUNTIF($K25:$BP25,"No (incorrect)")+COUNTIF($K25:$BP25,"Present")) -> 0.51 | H25: =((F25*(1/3))+(G25*(2/3))) -> 0.67333333 | J25: Sponsor | K25: Sponsor | L25: Sponsor | M25: Sponsor | N25: Sponsor | O25: Not sponsoring (correct) | P25: No | Q25: No | R25: Yes (correct) | S25: No | T25: Yes | U25: No | V25: Not on committee | W25: Not on committee | X25: Yes (correct) | Y25: Yes | Z25: No | AA25: No | AB25: No | AC25: Yes | AD25: No | AE25: No | AF25: No | AG25: No | AH25: No | AI25: No | AJ25: No | AK25: Yes | AL25: Yes | AM25: No | AN25: Yes | AO25: Not voting | AP25: Yes | AQ25: Yes | AR25: No | AS25: Yes | AT25: No | AU25: Yes | AV25: Present | AW25: No | AX25: Yes | AY25: No | AZ25: No | BA25: Yes | BB25: No | BC25: Yes | BD25: No | BE25: Yes | BF25: Yes | BG25: Yes | BH25: Yes | BI25: Yes | BJ25: Yes | BK25: Yes | BL25: Yes | BM25: Yes | BN25: Yes | BO25: No | BP25: Yes | BQ25: Non-signatory | BR25: Non-signatory | BS25: Non-signatory | BU25: =SUM(BV25:BY25) -> 0 | CA25: Yes
A26: =LOOKUP(H26,'Letter grades'!$A$1:$B$6) -> C | B26: =RANK(H26,H:H) -> 22 | C26: Nydia | D26: Velázquez | E26: NY-07 | F26: =((COUNTIF($J26:$BP26,"Sponsor")+COUNTIF($J26:$BP26, "Not sponsoring (correct)"))/(COUNTIF($J26:$BP26,"Sponsor")+COUNTIF($J26:$BP26,"Not sponsoring")+COUNTIF($J26:$BP26, "Not sponsoring (correct)")+COUNTIF($J26:$BP26, "Sponsor (incorrect)"))) -> 0.83333333 | G26: =(COUNTIF($K26:$BP26,"No")+COUNTIF($K26:$BP26,"Yes (correct)")+(COUNTIF($K26:$BP26,"Present")*0.5))/(COUNTIF($K26:$BP26,"Yes")+COUNTIF($K26:$BP26,"No")+COUNTIF($K26:$BP26,"Yes (correct)")+COUNTIF($K26:$BP26,"No (incorrect)")+COUNTIF($K26:$BP26,"Present")) -> 0.58823529 | H26: =((F26*(1/3))+(G26*(2/3))) -> 0.66993464 | I26: J Street | J26: Sponsor | K26: Sponsor | L26: Sponsor | M26: Sponsor | N26: Not sponsoring | O26: Not sponsoring (correct) | P26: No | Q26: No | R26: Yes (correct) | S26: No | T26: No | U26: No | V26: Not on committee | W26: Not on committee | X26: No (incorrect) | Y26: Yes | Z26: No | AA26: No | AB26: No | AC26: Yes | AD26: No | AE26: No | AF26: No | AG26: No | AH26: No | AI26: No | AJ26: No | AK26: Yes | AL26: Yes | AM26: No | AN26: Yes | AO26: Yes | AP26: No | AQ26: Yes | AR26: No | AS26: Yes | AT26: No | AU26: No | AV26: Present | AW26: Yes | AX26: Yes | AY26: No | AZ26: No | BA26: No | BB26: No | BC26: No | BD26: Present | BE26: No | BF26: Yes | BG26: Yes | BH26: No | BI26: No | BJ26: Yes | BK26: Yes | BL26: Yes | BM26: Yes | BN26: Yes | BO26: Yes | BP26: Yes | BQ26: Non-signatory | BR26: Non-signatory | BS26: Non-signatory | BU26: =SUM(BV26:BY26) -> 0 | CA26: Yes
